<?xml version="1.0" ?>
<robot name="robot_with_arm_and_camera" xmlns:xacro="http://www.ros.org/wiki/xacro">
    <!-- 添加虚拟链接 -->
    <link name="world" />
    <joint name="base_joint" type="fixed">
        <parent link="world" />
        <child link="base_link" />
        <origin xyz="0 0 0" rpy="0 0 0" />
    </joint>
    <!-- 基础链接 -->
    <link name="base_link">
        <visual>
            <geometry>
                <box size="0.1 0.1 0.1" />
            </geometry>
            <origin xyz="0 0 0.05" rpy="0 0 0" />
            <material name="blue">
                <color rgba="0 0 1 1" />
            </material>
        </visual>
        <collision>
            <geometry>
                <box size="0.1 0.1 0.1" />
            </geometry>
            <origin xyz="0 0 0.05" rpy="0 0 0" />
        </collision>
        <inertial>
            <mass value="10" />
            <origin xyz="0 0 0.05" rpy="0 0 0" />
            <inertia ixx="1" ixy="0.0" ixz="0.0" iyy="1" iyz="0.0" izz="1" />
        </inertial>
    </link>
    <!-- <joint name="base_link2base_footprint" type="fixed">
    <parent link="base_footprint"/>
    <child link="base_link"/>
    <origin xyz="0 0 0.002" rpy="0 0 0"/>
  </joint> -->
    <link name="link1">
        <visual>
            <geometry>
                <cylinder length="0.4" radius="0.05" />
            </geometry>
            <origin xyz="0 0 0.2" rpy="0 0 0" />
            <material name="green">
                <color rgba="0 1 0 1" />
            </material>
        </visual>
        <collision>
            <geometry>
                <cylinder length="0.4" radius="0.05" />
            </geometry>
            <origin xyz="0 0 0.2" rpy="0 0 0" />
        </collision>
        <inertial>
            <mass value="1.0" />
            <!-- 修改质量为1.0 -->
            <origin xyz="0 0 0.2" rpy="0 0 0" />
            <inertia ixx="1" ixy="0.0" ixz="0.0" iyy="1" iyz="0.0" izz="1" />
            <!-- 根据新质量重新计算转动惯量 -->
        </inertial>
    </link>
    <!-- 关节1 -->
    <joint name="joint1" type="revolute">
        <parent link="base_link" />
        <child link="link1" />
        <origin xyz="0 0 0.05" rpy="0 0 0" />
        <axis xyz="0 0 1" />
        <limit effort="100" lower="-10" upper="10" velocity="1.0" />
        <dynamics damping="1" friction="0.5" />
    </joint>
    <link name="link2">
        <visual>
            <geometry>
                <cylinder length="0.4" radius="0.05" />
            </geometry>
            <origin xyz="0 0 0.2" rpy="0 0 0" />
            <material name="yellow">
                <color rgba="1 1 0 1" />
            </material>
        </visual>
        <collision>
            <geometry>
                <cylinder length="0.4" radius="0.05" />
            </geometry>
            <origin xyz="0 0 0.2" rpy="0 0 0" />
        </collision>
        <inertial>
            <mass value="1.0" />
            <!-- 修改质量为1.0 -->
            <origin xyz="0 0 0.2" rpy="0 0 0" />
            <inertia ixx="1" ixy="0.0" ixz="0.0" iyy="1" iyz="0.0" izz="1" />
            <!-- 根据新质量重新计算转动惯量 -->
        </inertial>
    </link>
    <!-- 关节2 -->
    <joint name="joint2" type="revolute">
        <parent link="link1" />
        <child link="link2" />
        <origin xyz="0 0 0.4" rpy="0 0 0" />
        <axis xyz="0 1 0" />
        <limit effort="100.0" lower="-3.14" upper="3.14" velocity="1.0" />
        <dynamics damping="1" friction="0.5" />
    </joint>
    <link name="link3">
        <visual>
            <geometry>
                <cylinder length="0.4" radius="0.05" />
            </geometry>
            <origin xyz="0 0 0.2" rpy="0 0 0" />
            <material name="red">
                <color rgba="1 0 0 1" />
            </material>
        </visual>
        <collision>
            <geometry>
                <cylinder length="0.4" radius="0.05" />
            </geometry>
            <origin xyz="0 0 0.2" rpy="0 0 0" />
        </collision>
        <inertial>
            <mass value="1.0" />
            <!-- 修改质量为1.0 -->
            <origin xyz="0 0 0.2" rpy="0 0 0" />
            <inertia ixx="1" ixy="0.0" ixz="0.0" iyy="1" iyz="0.0" izz="1" />
            <!-- 根据新质量重新计算转动惯量 -->
        </inertial>
    </link>
    <!-- 关节3 -->
    <joint name="joint3" type="revolute">
        <parent link="link2" />
        <child link="link3" />
        <origin xyz="0 0 0.4" rpy="0 0 0" />
        <axis xyz="0 1 0" />
        <limit effort="100.0" lower="-3.14" upper="3.14" velocity="1.0" />
        <dynamics damping="1" friction="0.5" />
    </joint>
    <link name="link4">
        <visual>
            <geometry>
                <cylinder length="0.4" radius="0.05" />
            </geometry>
            <origin xyz="0 0 0.2" rpy="0 0 0" />
            <material name="cyan">
                <color rgba="0 1 1 1" />
            </material>
        </visual>
        <collision>
            <geometry>
                <cylinder length="0.4" radius="0.05" />
            </geometry>
            <origin xyz="0 0 0.2" rpy="0 0 0" />
        </collision>
        <inertial>
            <mass value="1.0" />
            <!-- 修改质量为1.0 -->
            <origin xyz="0 0 0.2" rpy="0 0 0" />
            <inertia ixx="1" ixy="0.0" ixz="0.0" iyy="1" iyz="0.0" izz="1" />
            <!-- 根据新质量重新计算转动惯量 -->
        </inertial>
    </link>
    <!-- 关节4 -->
    <joint name="joint4" type="revolute">
        <parent link="link3" />
        <child link="link4" />
        <origin xyz="0 0 0.4" rpy="0 0 0" />
        <axis xyz="1 0 0" />
        <limit effort="100.0" lower="-3.14" upper="3.14" velocity="1.0" />
        <dynamics damping="1" friction="0.5" />
    </joint>
    <link name="link5">
        <visual>
            <geometry>
                <cylinder length="0.4" radius="0.05" />
            </geometry>
            <origin xyz="0 0 0.2" rpy="0 0 0" />
            <material name="magenta">
                <color rgba="1 0 1 1" />
            </material>
        </visual>
        <collision>
            <geometry>
                <cylinder length="0.4" radius="0.05" />
            </geometry>
            <origin xyz="0 0 0.2" rpy="0 0 0" />
        </collision>
        <inertial>
            <mass value="1.0" />
            <!-- 修改质量为1.0 -->
            <origin xyz="0 0 0.2" rpy="0 0 0" />
            <inertia ixx="1" ixy="0.0" ixz="0.0" iyy="1" iyz="0.0" izz="1" />
            <!-- 根据新质量重新计算转动惯量 -->
        </inertial>
    </link>
    <!-- 关节5 -->
    <joint name="joint5" type="revolute">
        <parent link="link4" />
        <child link="link5" />
        <origin xyz="0 0 0.4" rpy="0 0 0" />
        <axis xyz="0 1 0" />
        <limit effort="100.0" lower="-3.14" upper="3.14" velocity="1.0" />
        <dynamics damping="1" friction="0.5" />
    </joint>
    <link name="link6">
        <visual>
            <geometry>
                <cylinder length="0.2" radius="0.05" />
            </geometry>
            <origin xyz="0 0 0.1" rpy="0 0 0" />
            <material name="white">
                <color rgba="1 1 1 1" />
            </material>
        </visual>
        <collision>
            <geometry>
                <cylinder length="0.2" radius="0.05" />
            </geometry>
            <origin xyz="0 0 0.1" rpy="0 0 0" />
        </collision>
        <inertial>
            <mass value="1.0" />
            <!-- 修改质量为1.0 -->
            <origin xyz="0 0 0.1" rpy="0 0 0" />
            <inertia ixx="1" ixy="0.0" ixz="0.0" iyy="1" iyz="0.0" izz="1" />
            <!-- 根据新质量重新计算转动惯量 -->
        </inertial>
    </link>
    <!-- 关节6 -->
    <joint name="joint6" type="revolute">
        <parent link="link5" />
        <child link="link6" />
        <origin xyz="0 0 0.4" rpy="0 0 0" />
        <axis xyz="1 0 0" />
        <limit effort="100.0" lower="-3.14" upper="3.14" velocity="1.0" />
        <dynamics damping="1" friction="0.5" />
    </joint>
    <!-- 夹具（真空吸盘） -->
    <joint name="vacuum_gripper_joint" type="revolute">
        <parent link="link6" />
        <child link="vacuum_gripper" />
        <origin xyz="0 0 0.2" rpy="0 0 0" />
        <axis xyz="0 1 0" />
        <limit effort="100.0" lower="-3.14" upper="3.14" velocity="1.0" />
        <dynamics damping="1" friction="0.5" />
    </joint>
    <link name="vacuum_gripper">
        <visual>
            <geometry>
                <cylinder length="0.2" radius="0.05" />
            </geometry>
            <origin xyz="0 0 0.1" rpy="0 0 0" />
            <material name="gray">
                <color rgba="0.5 0.5 0.5 1" />
            </material>
        </visual>
        <collision>
            <geometry>
                <cylinder length="0.2" radius="0.05" />
            </geometry>
            <origin xyz="0 0 0.1" rpy="0 0 0" />
        </collision>
        <inertial>
            <mass value="0.5" />
            <origin xyz="0 0 0.1" rpy="0 0 0" />
            <inertia ixx="0.1" ixy="0.0" ixz="0.0" iyy="0.1" iyz="0.0" izz="0.1" />
        </inertial>
        <gazebo reference="vacuum_gripper">
            <mu1>50</mu1>
            <mu2>50</mu2>
            <minDepth>0.003</minDepth>
            <maxVel>0</maxVel>
            <kp>1000000.0</kp>
            <kd>1.0</kd>
            <material>Gazebo/Grey</material>
        </gazebo>
    </link>
    <!-- Transmissions for ROS Control -->
    <xacro:macro name="transmission_block" params="joint_name">
        <transmission name="tran1">
            <type>transmission_interface/SimpleTransmission</type>
            <joint name="${joint_name}">
                <hardwareInterface>hardware_interface/EffortJointInterface</hardwareInterface>
            </joint>
            <actuator name="motor1">
                <hardwareInterface>hardware_interface/EffortJointInterface</hardwareInterface>
                <mechanicalReduction>1</mechanicalReduction>
            </actuator>
        </transmission>
    </xacro:macro>
    <xacro:transmission_block joint_name="joint1" />
    <xacro:transmission_block joint_name="joint2" />
    <xacro:transmission_block joint_name="joint3" />
    <xacro:transmission_block joint_name="joint4" />
    <xacro:transmission_block joint_name="joint5" />
    <xacro:transmission_block joint_name="joint6" />
    <xacro:transmission_block joint_name="vacuum_gripper_joint" />
    <!-- Gazebo插件 -->
    <gazebo>
        <plugin name="gazebo_ros_control" filename="libgazebo_ros_control.so">
            <robotNamespace>robot_with_arm_and_camera</robotNamespace>
            <!-- <robotSimType>gazebo_ros_control/DefaultRobotHWSim</robotSimType>
      <legacyModeNS>true</legacyModeNS> -->
        </plugin>
        <!-- <plugin name="gazebo_ros_vacuum_gripper" filename="libvacuum_plugin.so">
      <robotNamespace>six_dof_arm</robotNamespace>
      <bodyName>vacuum_gripper</bodyName>
      <topicName>grasping</topicName>
      <maxDistance>0.05</maxDistance>
      <minDistance>0.03</minDistance>
    </plugin> -->
        <plugin name="gazebo_ros_vacuum_gripper" filename="libgazebo_ros_vacuum_gripper.so">
            <robotNamespace>/robot_with_arm_and_camera/vacuum_gripper</robotNamespace>
            <bodyName>vacuum_gripper</bodyName>
            <topicName>grasping</topicName>
            <maxForce>5000</maxForce>
            <maxDistance>0.6</maxDistance>
            <minDistance>0.0</minDistance>
        </plugin>
    </gazebo>
    <gazebo reference="vacuum_gripper">
        <mu1>50</mu1>
        <mu2>50</mu2>
        <minDepth>0.003</minDepth>
        <maxVel>0</maxVel>
        <kp>1000000.0</kp>
        <kd>1.0</kd>
        <material>Gazebo/Grey</material>
    </gazebo>
    <!-- 定义深度相机的链接 -->
    <link name="depth_camera_link">
        <visual>
            <geometry>
                <box size="0.1 0.1 0.1" />
                <!-- 相机的尺寸 -->
            </geometry>
            <material name="gray">
                <color rgba="0.5 0.5 0.5 1.0" />
            </material>
        </visual>
        <collision>
            <geometry>
                <box size="0.1 0.1 0.1" />
                <!-- 相机的尺寸 -->
            </geometry>
            <material name="gray">
                <color rgba="0.5 0.5 0.5 1.0" />
            </material>
        </collision>
        <inertial>
            <mass value="0.1" />
            <origin xyz="0 0 0" rpy="0 0 0" />
            <inertia ixx="0.001" ixy="0.0" ixz="0.0" iyy="0.001" iyz="0.0" izz="0.001" />
        </inertial>
        <gazebo>
            <gravity>0</gravity>
            <!-- 设置无重力 -->
        </gazebo>
    </link>
    <!-- 定义深度相机的关节 -->
    <joint name="depth_camera_joint" type="fixed">
        <parent link="world" />
        <child link="depth_camera_link" />
        <origin xyz="-0.7 0.7 3" rpy="3.14159 0 0" />
    </joint>
    <!-- 定义深度相机传感器 -->
    <gazebo reference="depth_camera_link">
        <sensor type="depth" name="depth_camera_sensor">
            <update_rate>30</update_rate>
            <!-- 更新频率 -->
            <camera>
                <horizontal_fov>1.047</horizontal_fov>
                <!-- 水平视场角 -->
                <image>
                    <width>640</width>
                    <height>480</height>
                    <format>R8G8B8</format>
                </image>
                <clip>
                    <near>0.1</near>
                    <!-- 近剪切平面 -->
                    <far>10.0</far>
                    <!-- 远剪切平面 -->
                </clip>
            </camera>
            <plugin name="depth_camera_controller" filename="libgazebo_ros_depth_camera.so">
                <alwaysOn>true</alwaysOn>
                <updateRate>0.0</updateRate>
                <cameraName>depth_camera</cameraName>
                <frameName>depth_camera_link</frameName>
            </plugin>
        </sensor>
    </gazebo>
    <transmission name="trans_joint1">
        <type>transmission_interface/SimpleTransmission</type>
        <joint name="joint1">
            <hardwareInterface>hardware_interface/EffortJointInterface</hardwareInterface>
        </joint>
        <actuator name="joint1_motor">
            <hardwareInterface>hardware_interface/EffortJointInterface</hardwareInterface>
            <mechanicalReduction>1</mechanicalReduction>
        </actuator>
    </transmission>
    <transmission name="trans_joint2">
        <type>transmission_interface/SimpleTransmission</type>
        <joint name="joint2">
            <hardwareInterface>hardware_interface/EffortJointInterface</hardwareInterface>
        </joint>
        <actuator name="joint2_motor">
            <hardwareInterface>hardware_interface/EffortJointInterface</hardwareInterface>
            <mechanicalReduction>1</mechanicalReduction>
        </actuator>
    </transmission>
    <transmission name="trans_joint3">
        <type>transmission_interface/SimpleTransmission</type>
        <joint name="joint3">
            <hardwareInterface>hardware_interface/EffortJointInterface</hardwareInterface>
        </joint>
        <actuator name="joint3_motor">
            <hardwareInterface>hardware_interface/EffortJointInterface</hardwareInterface>
            <mechanicalReduction>1</mechanicalReduction>
        </actuator>
    </transmission>
    <transmission name="trans_joint4">
        <type>transmission_interface/SimpleTransmission</type>
        <joint name="joint4">
            <hardwareInterface>hardware_interface/EffortJointInterface</hardwareInterface>
        </joint>
        <actuator name="joint4_motor">
            <hardwareInterface>hardware_interface/EffortJointInterface</hardwareInterface>
            <mechanicalReduction>1</mechanicalReduction>
        </actuator>
    </transmission>
    <transmission name="trans_joint5">
        <type>transmission_interface/SimpleTransmission</type>
        <joint name="joint5">
            <hardwareInterface>hardware_interface/EffortJointInterface</hardwareInterface>
        </joint>
        <actuator name="joint5_motor">
            <hardwareInterface>hardware_interface/EffortJointInterface</hardwareInterface>
            <mechanicalReduction>1</mechanicalReduction>
        </actuator>
    </transmission>
    <transmission name="trans_joint6">
        <type>transmission_interface/SimpleTransmission</type>
        <joint name="joint6">
            <hardwareInterface>hardware_interface/EffortJointInterface</hardwareInterface>
        </joint>
        <actuator name="joint6_motor">
            <hardwareInterface>hardware_interface/EffortJointInterface</hardwareInterface>
            <mechanicalReduction>1</mechanicalReduction>
        </actuator>
    </transmission>
    <transmission name="trans_vacuum_gripper_joint">
        <type>transmission_interface/SimpleTransmission</type>
        <joint name="vacuum_gripper_joint">
            <hardwareInterface>hardware_interface/EffortJointInterface</hardwareInterface>
        </joint>
        <actuator name="vacuum_gripper_joint_motor">
            <hardwareInterface>hardware_interface/EffortJointInterface</hardwareInterface>
            <mechanicalReduction>1</mechanicalReduction>
        </actuator>
    </transmission>
</robot>

