<robot name="box_block">
  <link name="world">
        <visual>
            <geometry>
                <sphere radius="0.00001" />
            </geometry>
        </visual>
        <collision>
          <geometry>
                <sphere radius="0.00001" />
          </geometry>
        </collision>
  </link>

  <joint name="floating" type="floating">
    <origin xyz="0 0 0.2" rpy="0 0 0"/>
    <parent link="world"/>
    <child link="base_link"/>
  </joint>

  <link name="base_link">
    <visual>
      <geometry>
        <box size="0.1 0.1 0.02"/>  <!-- Box dimensions: 0.1m x 0.1m x 0.02m -->
      </geometry>
      <material name="Grey">
        <color rgba="0.5 0.5 0.5 1.0"/>  <!-- Grey color -->
      </material>
    </visual>
    <collision>
      <geometry>
        <box size="0.1 0.1 0.02"/>  <!-- Same dimensions for collision -->
      </geometry>
      <surface>
        <friction>
          <ode>
            <mu>1.0</mu>
            <mu2>1.0</mu2>
          </ode>
        </friction>
      </surface>
    </collision>
    <inertial>
      <mass value="0.1"/>  <!-- Assuming a mass of 0.1kg -->
      <inertia ixx="0.0001" ixy="0.0" ixz="0.0" iyy="0.0001" iyz="0.0" izz="0.0001"/>
    </inertial>
  </link>

  <gazebo reference="base_link">
        <material>Gazebo/Red</material>
  </gazebo>

</robot>